Workbook

Sheet Read Me
A1: Drive Cycle & Range — Macon → Pooler (unload) → Plastic Express (charge) → Macon · cruise 25 mph
A2: SOC = State of Charge, the battery fuel gauge, in kWh (265 = full; 26.5 = the 10% reserve floor).
A3: SEVEN assumptions drive everything (Parameters, yellow). Consumption is flat: loaded 2.0 / empty 1.0 kWh/mi — the numbers as given, no invented speed curve.
A5: SHEET GUIDE
B6: Parameters — 7 assumptions, your ops allowances, 2 decision toggles. Derived arithmetic is hidden at the bottom.
B7: First Principles — the 12-zone ledger and the what-if speed table.
B8: Drive Cycle — mile / limit / mph, live kinematics (v² changes ≤180 per 0.1-mile row).
B9: Dwell Plans — charge solver + chronological energy & time ledger (using and depleting, correlated to time).
B10: Time Budget — your ops allowance list vs the 24-h roundtrip and 48-h reefer constraints.
B11: SOC Waterfall — battery vs route mile; drain is shallower on the empty return.
A13: KEY RESULTS: empty return (1.0 kWh/mi) fits the pack nonstop — no westbound charge stop (break-even ~1.47 kWh/mi).
A14: CHARGING IS THE BINDING CONSTRAINT: each cycle needs ~486 kWh of charge. At the planned 40 kW mobile charger that is ~12 h
A15: of plug time -> ~29-h cycle, MISSING the 24-h target. See the Scenarios sheet for the options (2×40 kW, 4th vehicle, slow fallback).
A17: SPOT CHECKS: Drive Cycle mile 2.1 = 16.73 · 6.1 = 24.08 · 48.9 = 16.73 · First Principles totals 159.1 mi / 451 min

Sheet Parameters
A1: Parameter | B1: Value | C1: Note
A2: cruise speed (mph) | B2: 25 | C2: the decision: run the track limit
A3: acceleration / braking (mph/s) | B3: 0.25 | C3: PLACEHOLDER — engineering to replace
A4: consumption LOADED (kWh/mi) | B4: 2 | C4: PLACEHOLDER — as quoted; flat at all speeds
A5: consumption EMPTY (kWh/mi) | B5: 1 | C5: PLACEHOLDER — ops estimate; verify on shakedown
A6: battery pack (kWh) | B6: 265 | C6: midpoint of 260–270
A7: reserve floor (fraction) | B7: 0.1 | C7: policy: never plan below 10%
A8: charge power (kW) | B8: 40 | C8: fast DC mobile charger — planned vehicle upgrade; see Scenarios
A9: — OPS ALLOWANCES (your numbers) —
A10: off-power loading @ Macon (min) | B10: 30
A11: Macon hand-throw switch (min) | B11: 10
A12: get on charging track (min) | B12: 15
A13: stop charging, back on route (min) | B13: 15
A14: Pooler switch & positioning (min) | B14: 15
A15: port ramp/dray/ingate/shore power (min) | B15: 360
A16: max roundtrip per vehicle (h) | B16: 24
A17: max reefer off-power (h) | B17: 48
A18: — DECISIONS —
A19: include port time in VEHICLE cycle (0/1) | B19: 0 | C19: 1 breaks the 24-h budget; dray usually decouples
A20: Macon top-up charge to full (0/1) | B20: 1 | C20: needed so each cycle starts full
A21: — derived (hidden) —
A22: 2a converted (mi/h²) | B22: =2*3600*B3
A23: drive-cycle grid (mi) | B23: 0.1
A24: per-row v² change | B24: =B22*B23
A25: floor (kWh) | B25: =B6*B7
A26: scheduled Vidalia dwell for comparison (min) | B26: 25

Sheet First Principles
A1: Per-zone ledger — G&W 'Authorized Speed by MP' (presentation p.6). Savannah Sub: chainage = 92.3 + (577.8 − MP). Service ends at Pooler (159.1); vehicle continues 3.0 mi to Plastic Express to charge.
A3: Sub | B3: MP range | C3: mph | D3: Chainage | E3: Miles traversed | F3: Min @ limit | G3: Note
A4: Macon | B4: 0.0 – 2.0 | C4: 10 | D4: 0.0 – 2.0 | E4: 2 | F4: =IF(C4=0,0,E4/C4*60)
A5: Macon | B5: 2.0 – 6.0 | C5: 20 | D5: 2.0 – 6.0 | E5: 4 | F5: =IF(C5=0,0,E5/C5*60)
A6: Macon | B6: 6.0 – 49.0 | C6: 25 | D6: 6.0 – 49.0 | E6: 43 | F6: =IF(C6=0,0,E6/C6*60)
A7: Macon | B7: 49.0 – 58.6 | C7: 10 | D7: 49.0 – 58.6 | E7: 9.6 | F7: =IF(C7=0,0,E7/C7*60) | G7: Dublin Yard
A8: Macon | B8: 58.6 – 91.3 | C8: 25 | D8: 58.6 – 91.3 | E8: 32.7 | F8: =IF(C8=0,0,E8/C8*60)
A9: Macon | B9: 91.3 – 92.3 | C9: 10 | D9: 91.3 – 92.3 | E9: 1 | F9: =IF(C9=0,0,E9/C9*60) | G9: Vidalia approach
A10: Savannah | B10: 577.8 – 575.6 | C10: 10 | D10: 92.3 – 94.5 | E10: 2.2 | F10: =IF(C10=0,0,E10/C10*60)
A11: Savannah | B11: 575.6 – 558.0 | C11: 25 | D11: 94.5 – 112.1 | E11: 17.6 | F11: =IF(C11=0,0,E11/C11*60)
A12: Savannah | B12: 558.0 – 556.0 | C12: 10 | D12: 112.1 – 114.1 | E12: 2 | F12: =IF(C12=0,0,E12/C12*60) | G12: Collins Yard
A13: Savannah | B13: 556.0 – 521.5 | C13: 25 | D13: 114.1 – 148.6 | E13: 34.5 | F13: =IF(C13=0,0,E13/C13*60)
A14: Savannah | B14: 521.5 – 504.0 | C14: 20 | D14: 148.6 – 166.1 | E14: 10.5 | F14: =IF(C14=0,0,E14/C14*60) | G14: truncated at Pooler 159.1
A15: Savannah | B15: 504.0 – 499.0 | C15: 10 | D15: 166.1 – 171.1 | E15: 0 | F15: =IF(C15=0,0,E15/C15*60) | G15: beyond Pooler — not traversed
A16: TOTALS | E16: =SUM(E4:E15) | F16: =SUM(F4:F15) | G16: closure: 159.1 mi · 451 min = 7 h 31 m
A18: WHAT-IF: slower cruise speeds (for reference — the plan runs 25)
A19: cruise mph | B19: 10-zone min (fixed) | C19: 20-zone min | D19: 25-zone min | E19: one-way total min | F19: one-way h:mm
A20: 25 | B20: =16.8/10*60 | C20: =14.5/MIN(A20,20)*60 | D20: =127.8/MIN(A20,25)*60 | E20: =SUM(B20:D20) | F20: =TEXT(E20/1440,"h:mm")
A21: 24 | B21: =16.8/10*60 | C21: =14.5/MIN(A21,20)*60 | D21: =127.8/MIN(A21,25)*60 | E21: =SUM(B21:D21) | F21: =TEXT(E21/1440,"h:mm")
A22: 23 | B22: =16.8/10*60 | C22: =14.5/MIN(A22,20)*60 | D22: =127.8/MIN(A22,25)*60 | E22: =SUM(B22:D22) | F22: =TEXT(E22/1440,"h:mm")
A23: 22 | B23: =16.8/10*60 | C23: =14.5/MIN(A23,20)*60 | D23: =127.8/MIN(A23,25)*60 | E23: =SUM(B23:D23) | F23: =TEXT(E23/1440,"h:mm")
A24: 21 | B24: =16.8/10*60 | C24: =14.5/MIN(A24,20)*60 | D24: =127.8/MIN(A24,25)*60 | E24: =SUM(B24:D24) | F24: =TEXT(E24/1440,"h:mm")
A25: 20 | B25: =16.8/10*60 | C25: =14.5/MIN(A25,20)*60 | D25: =127.8/MIN(A25,25)*60 | E25: =SUM(B25:D25) | F25: =TEXT(E25/1440,"h:mm")
A26: 19 | B26: =16.8/10*60 | C26: =14.5/MIN(A26,20)*60 | D26: =127.8/MIN(A26,25)*60 | E26: =SUM(B26:D26) | F26: =TEXT(E26/1440,"h:mm")
A27: 18 | B27: =16.8/10*60 | C27: =14.5/MIN(A27,20)*60 | D27: =127.8/MIN(A27,25)*60 | E27: =SUM(B27:D27) | F27: =TEXT(E27/1440,"h:mm")

Sheet Drive Cycle
A1: mile | B1: limit (mph) | C1: mph | D1: fwd v² (helper) | E1: final v² (helper)
A2: 0 | B2: 0 | C2: =ROUND(SQRT(E2),2) | D2: =MIN(B2,Parameters!$B$2)^2 | E2: =MIN(D2, E3+Parameters!$B$24)
A3: 0.1 | B3: 10 | C3: =ROUND(SQRT(E3),2) | D3: =MIN(MIN(B3,Parameters!$B$2)^2, D2+Parameters!$B$24) | E3: =MIN(D3, E4+Parameters!$B$24)
A4: 0.2 | B4: 10 | C4: =ROUND(SQRT(E4),2) | D4: =MIN(MIN(B4,Parameters!$B$2)^2, D3+Parameters!$B$24) | E4: =MIN(D4, E5+Parameters!$B$24)
A5: 0.3 | B5: 10 | C5: =ROUND(SQRT(E5),2) | D5: =MIN(MIN(B5,Parameters!$B$2)^2, D4+Parameters!$B$24) | E5: =MIN(D5, E6+Parameters!$B$24)
A6: 0.4 | B6: 10 | C6: =ROUND(SQRT(E6),2) | D6: =MIN(MIN(B6,Parameters!$B$2)^2, D5+Parameters!$B$24) | E6: =MIN(D6, E7+Parameters!$B$24)
A7: 0.5 | B7: 10 | C7: =ROUND(SQRT(E7),2) | D7: =MIN(MIN(B7,Parameters!$B$2)^2, D6+Parameters!$B$24) | E7: =MIN(D7, E8+Parameters!$B$24)
A8: 0.6 | B8: 10 | C8: =ROUND(SQRT(E8),2) | D8: =MIN(MIN(B8,Parameters!$B$2)^2, D7+Parameters!$B$24) | E8: =MIN(D8, E9+Parameters!$B$24)
A9: 0.7 | B9: 10 | C9: =ROUND(SQRT(E9),2) | D9: =MIN(MIN(B9,Parameters!$B$2)^2, D8+Parameters!$B$24) | E9: =MIN(D9, E10+Parameters!$B$24)
A10: 0.8 | B10: 10 | C10: =ROUND(SQRT(E10),2) | D10: =MIN(MIN(B10,Parameters!$B$2)^2, D9+Parameters!$B$24) | E10: =MIN(D10, E11+Parameters!$B$24)
A11: 0.9 | B11: 10 | C11: =ROUND(SQRT(E11),2) | D11: =MIN(MIN(B11,Parameters!$B$2)^2, D10+Parameters!$B$24) | E11: =MIN(D11, E12+Parameters!$B$24)
A12: 1 | B12: 10 | C12: =ROUND(SQRT(E12),2) | D12: =MIN(MIN(B12,Parameters!$B$2)^2, D11+Parameters!$B$24) | E12: =MIN(D12, E13+Parameters!$B$24)
A13: 1.1 | B13: 10 | C13: =ROUND(SQRT(E13),2) | D13: =MIN(MIN(B13,Parameters!$B$2)^2, D12+Parameters!$B$24) | E13: =MIN(D13, E14+Parameters!$B$24)
A14: 1.2 | B14: 10 | C14: =ROUND(SQRT(E14),2) | D14: =MIN(MIN(B14,Parameters!$B$2)^2, D13+Parameters!$B$24) | E14: =MIN(D14, E15+Parameters!$B$24)
... A1622: 162 | B1622: 20 | C1622: =ROUND(SQRT(E1622),2) | D1622: =MIN(MIN(B1622,Parameters!$B$2)^2, D1621+Parameters!$B$24) | E1622: =MIN(D1622, E1623+Parameters!$B$24)
A1623: 162.1 | B1623: 0 | C1623: =ROUND(SQRT(E1623),2) | D1623: =MIN(MIN(B1623,Parameters!$B$2)^2, D1622+Parameters!$B$24) | E1623: =D1623

Sheet Dwell Plans
A1: Charge solver (top) and the chronological energy & time ledger (below). Energy = miles × consumption; flat rates.
A3: Solver | B3: kWh (loaded legs) | D3: kWh (empty legs)
A4: E Macon→Vidalia (94.5 mi) | B4: =94.5*Parameters!$B$4 | D4: =67.6*Parameters!$B$5
A5: E Vidalia→Pooler (64.6 mi) | B5: =64.6*Parameters!$B$4 | D5: =94.5*Parameters!$B$5
A6: E Pooler→Plastic (3.0 mi) | B6: =3*Parameters!$B$4 | D6: =D4+D5
A7: arrive Vidalia EB | B7: =Parameters!$B$6-B4
A8: c1 Vidalia EB charge | B8: =MAX(0,Parameters!$B$25+B5+B6-B7)
A9: arrive Plastic Express | B9: =B7+B8-B5-B6
A10: c2 Plastic charge (banks the empty return) | B10: =MIN(MAX(0,Parameters!$B$25+D6-B9),Parameters!$B$6-B9)
A11: arrive Vidalia WB | B11: =B9+B10-D4
A12: c3 Vidalia WB charge (0 if empty return fits) | B12: =MAX(0,Parameters!$B$25+D5-B11)
A13: end SOC at Macon | B13: =B11+B12-D5
A14: c1 minutes | B14: =ROUNDUP(B8/Parameters!$B$8*60,0)
A15: c2 minutes | B15: =ROUNDUP(B10/Parameters!$B$8*60,0)
A16: c3 minutes | B16: =ROUNDUP(B12/Parameters!$B$8*60,0)
A17: Macon top-up to full (kWh) | B17: =Parameters!$B$6-B13
A18: Macon top-up minutes | B18: =ROUNDUP(B17/Parameters!$B$8*60,0)*Parameters!$B$20
A20: CHRONOLOGICAL LEDGER — using & depleting, correlated to time
A21: Event | B21: Miles | C21: Time (min) | D21: Energy Δ (kWh) | E21: SOC after (kWh) | F21: Note
A22: Depart Macon (full pack, loaded) | B22: 0 | C22: 0 | D22: 0 | E22: =Parameters!$B$6 | F22: start of cycle
A23: Run Macon → Vidalia | B23: 94.5 | C23: =(14.8/10*60+4/MIN(20,Parameters!$B$2)*60+75.7/MIN(25,Parameters!$B$2)*60) | D23: =-'Dwell Plans'!B4 | E23: =E22+D23 | F23: loaded
A24: CHARGE at Vidalia | B24: 0 | C24: ='Dwell Plans'!B14 | D24: ='Dwell Plans'!B8 | E24: =E23+D24 | F24: enough to reach Plastic above the floor
A25: Run Vidalia → Pooler | B25: 64.6 | C25: =(2/10*60+52.1/MIN(25,Parameters!$B$2)*60+10.5/MIN(20,Parameters!$B$2)*60) | D25: =-'Dwell Plans'!B5 | E25: =E24+D25 | F25: loaded
A26: Unload at Pooler | B26: 0 | C26: =Parameters!$B$14 | D26: 0 | E26: =E25+D26 | F26: switch & positioning
A27: Run Pooler → Plastic Express | B27: 3.0 | C27: =(3/MIN(20,Parameters!$B$2)*60) | D27: =-'Dwell Plans'!B6 | E27: =E26+D27 | F27: loaded (last loaded mile)
A28: CHARGE at Plastic Express | B28: 0 | C28: ='Dwell Plans'!B15 | D28: ='Dwell Plans'!B10 | E28: =E27+D28 | F28: banks the whole empty return
A29: Run Plastic → Vidalia (EMPTY) | B29: 67.6 | C29: =(3/MIN(20,Parameters!$B$2)*60)+(2/10*60+52.1/MIN(25,Parameters!$B$2)*60+10.5/MIN(20,Parameters!$B$2)*60) | D29: =-'Dwell Plans'!D4 | E29: =E28+D29 | F29: empty rate
A30: CHARGE at Vidalia WB (usually 0) | B30: 0 | C30: ='Dwell Plans'!B16 | D30: ='Dwell Plans'!B12 | E30: =E29+D30 | F30: flips on only if empty > ~1.47 kWh/mi
A31: Run Vidalia → Macon (EMPTY) | B31: 94.5 | C31: =(14.8/10*60+4/MIN(20,Parameters!$B$2)*60+75.7/MIN(25,Parameters!$B$2)*60) | D31: =-'Dwell Plans'!D5 | E31: =E30+D31 | F31: empty rate
A32: CHARGE at Macon to full (toggle) | B32: 0 | C32: ='Dwell Plans'!B18 | D32: ='Dwell Plans'!B17*Parameters!$B$20 | E32: =E31+D32 | F32: so the next cycle starts full
A33: TOTALS | B33: =2*162.1 | C33: =SUM(C22:C32) | D33: =SUM(D22:D32) | F33: =TEXT(C33/1440,"h:mm")&" movement+charging — full cycle on Time Budget"

Sheet Time Budget
A1: Time budget — start with the budget, spend it down. Detail rows at the bottom are the audit trail.
A3: VEHICLE CYCLE vs the 24-h target | B3: minutes | C3: h:mm | D3: note
A4: daily budget | B4: =Parameters!$B$16*60 | C4: =IF(B4<0,"−","")&TEXT(ABS(B4)/1440,"h:mm") | D4: max roundtrip (Parameters)
A5: − driving, both ways | B5: =-(2*(14.8/10*60+4/MIN(20,Parameters!$B$2)*60+75.7/MIN(25,Parameters!$B$2)*60)+2*(2/10*60+52.1/MIN(25,Parameters!$B$2)*60+10.5/MIN(20,Parameters!$B$2)*60)+2*(3/MIN(20,Parameters!$B$2)*60)) | C5: =IF(B5<0,"−","")&TEXT(ABS(B5)/1440,"h:mm") | D5: zone math; the railroad's price — untouchable
A6: − handling allowances | B6: =-(Parameters!$B$10+Parameters!$B$11+Parameters!$B$12+Parameters!$B$13+Parameters!$B$14+Parameters!$B$15*Parameters!$B$19+IF('Dwell Plans'!B12>0,Parameters!$B$12+Parameters!$B$13,0)) | C6: =IF(B6<0,"−","")&TEXT(ABS(B6)/1440,"h:mm") | D6: load, switches, on/off charge track, port per toggle
A7: =left over for charging | B7: =B4+B5+B6 | C7: =IF(B7<0,"−","")&TEXT(ABS(B7)/1440,"h:mm")
A8: − charging actually needed | B8: =-('Dwell Plans'!B14+'Dwell Plans'!B15+'Dwell Plans'!B16+'Dwell Plans'!B18) | C8: =IF(B8<0,"−","")&TEXT(ABS(B8)/1440,"h:mm") | D8: Vidalia + Plastic + (WB if any) + Macon top-up
A9: =SPARE (+) or SHORTFALL (−) | B9: =B7+B8 | C9: =IF(B9<0,"−","")&TEXT(ABS(B9)/1440,"h:mm") | D9: =IF(B9>=0,"PASS — fits the 24-h cycle","FAIL — does not fit; see Scenarios for options")
A11: REEFER OFF-POWER vs the 48-h limit
A12: reefer budget | B12: =Parameters!$B$17*60 | C12: =IF(B12<0,"−","")&TEXT(ABS(B12)/1440,"h:mm") | D12: max off-power (Parameters)
A13: − unplugged: load → shore power | B13: =-(Parameters!$B$10+Parameters!$B$11+(14.8/10*60+4/MIN(20,Parameters!$B$2)*60+75.7/MIN(25,Parameters!$B$2)*60)+Parameters!$B$12+'Dwell Plans'!B14+Parameters!$B$13+(2/10*60+52.1/MIN(25,Parameters!$B$2)*60+10.5/MIN(20,Parameters!$B$2)*60)+Parameters!$B$14+Parameters!$B$15) | C13: =IF(B13<0,"−","")&TEXT(ABS(B13)/1440,"h:mm") | D13: loading, switch, transit, Vidalia charge, transit, Pooler, full port sequence
A14: =SPARE | B14: =B12+B13 | C14: =IF(B14<0,"−","")&TEXT(ABS(B14)/1440,"h:mm") | D14: =IF(B14>=0,"PASS","FAIL")
A16: DETAIL — where every minute goes (audit trail)
A17: # | B17: Item | C17: Minutes | D17: In reefer clock? | E17: Source
A18: 1 | B18: Off-power loading @ Macon | C18: =Parameters!$B$10 | D18: 1 | E18: given
A19: 2 | B19: Macon hand-throw switch | C19: =Parameters!$B$11 | D19: 1 | E19: given
A20: 3 | B20: Movement Macon → charge point (Vidalia) | C20: =(14.8/10*60+4/MIN(20,Parameters!$B$2)*60+75.7/MIN(25,Parameters!$B$2)*60) | D20: 1 | E20: zone math
A21: 4 | B21: Get on charging track & start | C21: =Parameters!$B$12 | D21: 1 | E21: given
A22: 5 | B22: Charging @ Vidalia (dependent) | C22: ='Dwell Plans'!B14 | D22: 1 | E22: solver
A23: 6 | B23: Stop charging, back on route | C23: =Parameters!$B$13 | D23: 1 | E23: given
A24: 7 | B24: Movement Vidalia → Pooler | C24: =(2/10*60+52.1/MIN(25,Parameters!$B$2)*60+10.5/MIN(20,Parameters!$B$2)*60) | D24: 1 | E24: zone math
A25: 8 | B25: Pooler switch & positioning (unload) | C25: =Parameters!$B$14 | D25: 1 | E25: given
A26: 9 | B26: Port ramp/dray/ingate/shore power | C26: =Parameters!$B$15*Parameters!$B$19 | D26: reefer only | E26: toggle B19; ALWAYS in reefer clock
A27: 10 | B27: Movement Pooler → Plastic Express | C27: =(3/MIN(20,Parameters!$B$2)*60) | D27: 0 | E27: zone math
A28: 11 | B28: Recharge @ Plastic Express (dependent) | C28: ='Dwell Plans'!B15 | D28: 0 | E28: solver
A29: 12 | B29: Movement Plastic → Vidalia (empty) | C29: =(3/MIN(20,Parameters!$B$2)*60)+(2/10*60+52.1/MIN(25,Parameters!$B$2)*60+10.5/MIN(20,Parameters!$B$2)*60) | D29: 0 | E29: zone math
A30: 13 | B30: Get on charging track WB (if needed) | C30: =IF('Dwell Plans'!B12>0,Parameters!$B$12,0) | D30: 0 | E30: self-zeroing
A31: 14 | B31: Charging @ Vidalia WB (dependent) | C31: ='Dwell Plans'!B16 | D31: 0 | E31: 0 when empty return fits
A32: 15 | B32: Back on route WB (if needed) | C32: =IF('Dwell Plans'!B12>0,Parameters!$B$13,0) | D32: 0 | E32: self-zeroing
A33: 16 | B33: Movement Vidalia → Macon (empty) | C33: =(14.8/10*60+4/MIN(20,Parameters!$B$2)*60+75.7/MIN(25,Parameters!$B$2)*60) | D33: 0 | E33: zone math
A34: 17 | B34: Macon top-up charge (toggle) | C34: ='Dwell Plans'!B18 | D34: 0 | E34: Parameters B20

Sheet SOC Waterfall
A1: route mile | B1: kWh/mi (loaded out, empty back) | C1: SOC solver dwells (kWh) | D1: SOC scheduled 25-min dwells (kWh) | E1: floor
A2: 0 | B2: =IF(A2>162.1,Parameters!$B$5,Parameters!$B$4) | C2: =Parameters!$B$6 | D2: =Parameters!$B$6 | E2: =Parameters!$B$25
A3: 0.1 | B3: =IF(A3>162.1,Parameters!$B$5,Parameters!$B$4) | C3: =C2-0.1*B3+0 | D3: =D2-0.1*B3+0 | E3: =Parameters!$B$25
A4: 0.2 | B4: =IF(A4>162.1,Parameters!$B$5,Parameters!$B$4) | C4: =C3-0.1*B4+0 | D4: =D3-0.1*B4+0 | E4: =Parameters!$B$25
A5: 0.3 | B5: =IF(A5>162.1,Parameters!$B$5,Parameters!$B$4) | C5: =C4-0.1*B5+0 | D5: =D4-0.1*B5+0 | E5: =Parameters!$B$25
A6: 0.4 | B6: =IF(A6>162.1,Parameters!$B$5,Parameters!$B$4) | C6: =C5-0.1*B6+0 | D6: =D5-0.1*B6+0 | E6: =Parameters!$B$25
A7: 0.5 | B7: =IF(A7>162.1,Parameters!$B$5,Parameters!$B$4) | C7: =C6-0.1*B7+0 | D7: =D6-0.1*B7+0 | E7: =Parameters!$B$25
A8: 0.6 | B8: =IF(A8>162.1,Parameters!$B$5,Parameters!$B$4) | C8: =C7-0.1*B8+0 | D8: =D7-0.1*B8+0 | E8: =Parameters!$B$25
A9: 0.7 | B9: =IF(A9>162.1,Parameters!$B$5,Parameters!$B$4) | C9: =C8-0.1*B9+0 | D9: =D8-0.1*B9+0 | E9: =Parameters!$B$25
A10: 0.8 | B10: =IF(A10>162.1,Parameters!$B$5,Parameters!$B$4) | C10: =C9-0.1*B10+0 | D10: =D9-0.1*B10+0 | E10: =Parameters!$B$25
A11: 0.9 | B11: =IF(A11>162.1,Parameters!$B$5,Parameters!$B$4) | C11: =C10-0.1*B11+0 | D11: =D10-0.1*B11+0 | E11: =Parameters!$B$25
A12: 1 | B12: =IF(A12>162.1,Parameters!$B$5,Parameters!$B$4) | C12: =C11-0.1*B12+0 | D12: =D11-0.1*B12+0 | E12: =Parameters!$B$25
A13: 1.1 | B13: =IF(A13>162.1,Parameters!$B$5,Parameters!$B$4) | C13: =C12-0.1*B13+0 | D13: =D12-0.1*B13+0 | E13: =Parameters!$B$25
A14: 1.2 | B14: =IF(A14>162.1,Parameters!$B$5,Parameters!$B$4) | C14: =C13-0.1*B14+0 | D14: =D13-0.1*B14+0 | E14: =Parameters!$B$25
... A946: 94.4 | B946: =IF(A946>162.1,Parameters!$B$5,Parameters!$B$4) | C946: =C945-0.1*B946+0 | D946: =D945-0.1*B946+0 | E946: =Parameters!$B$25
A947: 94.5 | B947: =IF(A947>162.1,Parameters!$B$5,Parameters!$B$4) | C947: =C946-0.1*B947+'Dwell Plans'!$B$8 | D947: =D946-0.1*B947+MIN(Parameters!$B$26/60*Parameters!$B$8,Parameters!$B$6-(D946-0.1*B947)) | E947: =Parameters!$B$25
A948: 94.6 | B948: =IF(A948>162.1,Parameters!$B$5,Parameters!$B$4) | C948: =C947-0.1*B948+0 | D948: =D947-0.1*B948+0 | E948: =Parameters!$B$25
A949: 94.7 | B949: =IF(A949>162.1,Parameters!$B$5,Parameters!$B$4) | C949: =C948-0.1*B949+0 | D949: =D948-0.1*B949+0 | E949: =Parameters!$B$25
A950: 94.8 | B950: =IF(A950>162.1,Parameters!$B$5,Parameters!$B$4) | C950: =C949-0.1*B950+0 | D950: =D949-0.1*B950+0 | E950: =Parameters!$B$25
A951: 94.9 | B951: =IF(A951>162.1,Parameters!$B$5,Parameters!$B$4) | C951: =C950-0.1*B951+0 | D951: =D950-0.1*B951+0 | E951: =Parameters!$B$25
A952: 95 | B952: =IF(A952>162.1,Parameters!$B$5,Parameters!$B$4) | C952: =C951-0.1*B952+0 | D952: =D951-0.1*B952+0 | E952: =Parameters!$B$25
A953: 95.1 | B953: =IF(A953>162.1,Parameters!$B$5,Parameters!$B$4) | C953: =C952-0.1*B953+0 | D953: =D952-0.1*B953+0 | E953: =Parameters!$B$25
A954: 95.2 | B954: =IF(A954>162.1,Parameters!$B$5,Parameters!$B$4) | C954: =C953-0.1*B954+0 | D954: =D953-0.1*B954+0 | E954: =Parameters!$B$25
A955: 95.3 | B955: =IF(A955>162.1,Parameters!$B$5,Parameters!$B$4) | C955: =C954-0.1*B955+0 | D955: =D954-0.1*B955+0 | E955: =Parameters!$B$25
A956: 95.4 | B956: =IF(A956>162.1,Parameters!$B$5,Parameters!$B$4) | C956: =C955-0.1*B956+0 | D956: =D955-0.1*B956+0 | E956: =Parameters!$B$25
A957: 95.5 | B957: =IF(A957>162.1,Parameters!$B$5,Parameters!$B$4) | C957: =C956-0.1*B957+0 | D957: =D956-0.1*B957+0 | E957: =Parameters!$B$25
A958: 95.6 | B958: =IF(A958>162.1,Parameters!$B$5,Parameters!$B$4) | C958: =C957-0.1*B958+0 | D958: =D957-0.1*B958+0 | E958: =Parameters!$B$25
A959: 95.7 | B959: =IF(A959>162.1,Parameters!$B$5,Parameters!$B$4) | C959: =C958-0.1*B959+0 | D959: =D958-0.1*B959+0 | E959: =Parameters!$B$25
... A1622: 162 | B1622: =IF(A1622>162.1,Parameters!$B$5,Parameters!$B$4) | C1622: =C1621-0.1*B1622+0 | D1622: =D1621-0.1*B1622+0 | E1622: =Parameters!$B$25
A1623: 162.1 | B1623: =IF(A1623>162.1,Parameters!$B$5,Parameters!$B$4) | C1623: =C1622-0.1*B1623+'Dwell Plans'!$B$10 | D1623: =D1622-0.1*B1623+MIN(60/60*Parameters!$B$8,Parameters!$B$6-(D1622-0.1*B1623)) | E1623: =Parameters!$B$25
A1624: 162.2 | B1624: =IF(A1624>162.1,Parameters!$B$5,Parameters!$B$4) | C1624: =C1623-0.1*B1624+0 | D1624: =D1623-0.1*B1624+0 | E1624: =Parameters!$B$25
A1625: 162.3 | B1625: =IF(A1625>162.1,Parameters!$B$5,Parameters!$B$4) | C1625: =C1624-0.1*B1625+0 | D1625: =D1624-0.1*B1625+0 | E1625: =Parameters!$B$25
A1626: 162.4 | B1626: =IF(A1626>162.1,Parameters!$B$5,Parameters!$B$4) | C1626: =C1625-0.1*B1626+0 | D1626: =D1625-0.1*B1626+0 | E1626: =Parameters!$B$25
A1627: 162.5 | B1627: =IF(A1627>162.1,Parameters!$B$5,Parameters!$B$4) | C1627: =C1626-0.1*B1627+0 | D1627: =D1626-0.1*B1627+0 | E1627: =Parameters!$B$25
A1628: 162.6 | B1628: =IF(A1628>162.1,Parameters!$B$5,Parameters!$B$4) | C1628: =C1627-0.1*B1628+0 | D1628: =D1627-0.1*B1628+0 | E1628: =Parameters!$B$25
A1629: 162.7 | B1629: =IF(A1629>162.1,Parameters!$B$5,Parameters!$B$4) | C1629: =C1628-0.1*B1629+0 | D1629: =D1628-0.1*B1629+0 | E1629: =Parameters!$B$25
A1630: 162.8 | B1630: =IF(A1630>162.1,Parameters!$B$5,Parameters!$B$4) | C1630: =C1629-0.1*B1630+0 | D1630: =D1629-0.1*B1630+0 | E1630: =Parameters!$B$25
A1631: 162.9 | B1631: =IF(A1631>162.1,Parameters!$B$5,Parameters!$B$4) | C1631: =C1630-0.1*B1631+0 | D1631: =D1630-0.1*B1631+0 | E1631: =Parameters!$B$25
A1632: 163 | B1632: =IF(A1632>162.1,Parameters!$B$5,Parameters!$B$4) | C1632: =C1631-0.1*B1632+0 | D1632: =D1631-0.1*B1632+0 | E1632: =Parameters!$B$25
A1633: 163.1 | B1633: =IF(A1633>162.1,Parameters!$B$5,Parameters!$B$4) | C1633: =C1632-0.1*B1633+0 | D1633: =D1632-0.1*B1633+0 | E1633: =Parameters!$B$25
...

Sheet Scenarios
A1: Charging scenarios — same physics, different plug power. All formulas; edit column A to test any power.
A3: Fixed (non-charging) cycle time, min | B3: =2*(14.8/10*60+4/MIN(20,Parameters!$B$2)*60+75.7/MIN(25,Parameters!$B$2)*60)+2*(2/10*60+52.1/MIN(25,Parameters!$B$2)*60+10.5/MIN(20,Parameters!$B$2)*60)+2*(3/MIN(20,Parameters!$B$2)*60)+Parameters!$B$10+Parameters!$B$11+Parameters!$B$12+Parameters!$B$13+Parameters!$B$14+Parameters!$B$15*Parameters!$B$19 | C3: movement + allowances (port per toggle)
A4: Charge energy per cycle, kWh | B4: ='Dwell Plans'!B8+'Dwell Plans'!B10+'Dwell Plans'!B12+'Dwell Plans'!B17*Parameters!$B$20 | C4: Vidalia + Plastic + (WB if any) + Macon top-up
A6: charge power (kW) | B6: scenario | C6: charging h/cycle | D6: cycle h | E6: vs 24 h | F6: loads/day (3 vehicles) | G6: vehicles for 3 loads/day
A7: 40 | B7: planned: one 40 kW DC mobile charger | C7: =$B$4/A7 | D7: =$B$3/60+C7 | E7: =IF(D7<=Parameters!$B$16,"PASS — margin "&TEXT((Parameters!$B$16-D7)/24,"h:mm"),"FAIL — over by "&TEXT((D7-Parameters!$B$16)/24,"h:mm")) | F7: =ROUND(3*24/D7,2) | G7: =ROUNDUP(D7/(Parameters!$B$16/3),0)
A8: 80 | B8: two 40 kW mobile units charging simultaneously | C8: =$B$4/A8 | D8: =$B$3/60+C8 | E8: =IF(D8<=Parameters!$B$16,"PASS — margin "&TEXT((Parameters!$B$16-D8)/24,"h:mm"),"FAIL — over by "&TEXT((D8-Parameters!$B$16)/24,"h:mm")) | F8: =ROUND(3*24/D8,2) | G8: =ROUNDUP(D8/(Parameters!$B$16/3),0)
A9: 11 | B9: fallback: no fast charge (24 h empty→full) | C9: =$B$4/A9 | D9: =$B$3/60+C9 | E9: =IF(D9<=Parameters!$B$16,"PASS — margin "&TEXT((Parameters!$B$16-D9)/24,"h:mm"),"FAIL — over by "&TEXT((D9-Parameters!$B$16)/24,"h:mm")) | F9: =ROUND(3*24/D9,2) | G9: =ROUNDUP(D9/(Parameters!$B$16/3),0)
A10: 9.5 | B10: fallback: no fast charge (28 h empty→full) | C10: =$B$4/A10 | D10: =$B$3/60+C10 | E10: =IF(D10<=Parameters!$B$16,"PASS — margin "&TEXT((Parameters!$B$16-D10)/24,"h:mm"),"FAIL — over by "&TEXT((D10-Parameters!$B$16)/24,"h:mm")) | F10: =ROUND(3*24/D10,2) | G10: =ROUNDUP(D10/(Parameters!$B$16/3),0)
A11: 67 | B11: minimum that exactly meets 24 h | C11: =$B$4/A11 | D11: =$B$3/60+C11 | E11: =IF(D11<=Parameters!$B$16,"PASS — margin "&TEXT((Parameters!$B$16-D11)/24,"h:mm"),"FAIL — over by "&TEXT((D11-Parameters!$B$16)/24,"h:mm")) | F11: =ROUND(3*24/D11,2) | G11: =ROUNDUP(D11/(Parameters!$B$16/3),0)
A12: 150 | B12: prior planning assumption (reference) | C12: =$B$4/A12 | D12: =$B$3/60+C12 | E12: =IF(D12<=Parameters!$B$16,"PASS — margin "&TEXT((Parameters!$B$16-D12)/24,"h:mm"),"FAIL — over by "&TEXT((D12-Parameters!$B$16)/24,"h:mm")) | F12: =ROUND(3*24/D12,2) | G12: =ROUNDUP(D12/(Parameters!$B$16/3),0)
A14: Reading: a load departs every (cycle ÷ fleet size) hours. 3 loads/day needs a departure every 8 h, so vehicles required = cycle ÷ 8, rounded up.
